<mujoco model="cartpole">
    <compiler angle="radian" coordinate="local" />
    <option timestep="0.01" gravity="0 0 -9.81" />
    
    <worldbody>
        <!-- <geom name="floor" type="plane" size="10 10 0.1" rgba="0.5 0.5 0.5 1" /> -->

        <body name="cart" pos="0 0 .1">
            <joint name="cart_joint" type="slide" axis="1 0 0" range="-2.4 2.4" damping="1.0"/>
            <geom type="box" size="0.1 0.1 0.05" rgba="0.2 0.7 0.2 1" mass="1" friction="1.0 0.2 0.001"/>
            <!-- <inertial pos=".05 .05 .025" mass="1" diaginertia="1 1 1"/> -->
                <body name="link1" pos="0 0 .05">
                    <joint name="hinge" type="hinge" axis="0 1 0" range="-6.28 6.28" />
                    <geom type="capsule" fromto="0 0 0 0 0 .3" size="0.03" rgba="0.2 0.2 0.7 1" mass="1"/>
                    <!-- <inertial pos=".05 0 .15" mass=".5" diaginertia="1 1 1"/> -->
                
                </body>
        </body>
    </worldbody>
    
    <actuator>
        <motor name="cart_motor" joint="cart_joint" gear="1" ctrllimited="true" ctrlrange="-10 10" />
	
    </actuator>
</mujoco>
